Workbook

Sheet EJECUTIVO
C1: ALCALDÍA DE RIONEGRO · SECRETARÍA DE EDUCACIÓN | AB1: Etapa | AC1: Valor | AE1: Componente | AF1: Definitivo
C2: INFORME DE EJECUCIÓN PRESUPUESTAL — RESUMEN EJECUTIVO | AB2: Presupuesto Definitivo | AC2: =B7 | AE2: VIGENCIAS ANTERIORES | AF2: =B182
C3: Corte: 15 de septiembre de 2026 | AB3: Reservado CDP | AC3: =F7 | AE3: INFRAESTRUCTURA | AF3: =B177
C4: Fuente: Presupuesto de egreso a 15_09_2026.xls | Generado: 2026-09-18 | Rubros: 127 | AB4: Comprometido RP | AC4: =J7 | AE4: CALIDAD GRATUIDAD | AF4: =B160
AB5: Obligado OPS | AC5: =N7 | AE5: PRIMERA INFANCIA | AF5: =B173
B6: PRESUPUESTO DEFINITIVO | F6: RESERVADO CDP | J6: COMPROMETIDO RP | N6: OBLIGADO OPS | R6: PAGADO | AB6: Pagado | AC6: =R7 | AE6: CALIDAD MATRICULA | AF6: =B148
B7: =SEGUIMIENTO!H144 | F7: =SEGUIMIENTO!I144 | J7: =SEGUIMIENTO!J144 | N7: =SEGUIMIENTO!K144 | R7: =SEGUIMIENTO!L144 | AE7: SGP - PGN - PAE | AF7: =B162
AE8: RENDIMIENTOS O RECURSOS DEL BALANCE DE PRESTACION DEL SERVICIO | AF8: =B144
B9: Presupuesto disponible durante la vigencia. | F9: =IFERROR(F7/B7,0) | J9: =IFERROR(J7/B7,0) | N9: =IFERROR(N7/B7,0) | R9: =IFERROR(R7/B7,0) | AE9: PRESTACION DEL SERVICIO | AF9: =B46
F10: Cuenta con Certificado de Disponibilidad Presupuestal. | J10: Respaldado por Registro Presupuestal (contrato/obligación). | N10: Bien o servicio recibido; obligación exigible. | R10: Giro efectivo realizado a la fecha de corte. | AE10: RECURSOS PROPIOS O LIBRE INVERSION | AF10: =B128
A13: BRECHA DE EJECUCIÓN
B14: SIN RESERVAR | F14: SIN COMPROMETER | J14: SIN OBLIGAR
B15: =B7-F7 | F15: =B7-J7 | J15: =B7-N7
B17: =IFERROR(B15/B7,0) | F17: =IFERROR(F15/B7,0) | J17: =IFERROR(J15/B7,0)
B18: Presupuesto definitivo que aún no tiene CDP (Certificado de Disponibilidad Presupuestal). | F18: Presupuesto definitivo que aún no está respaldado por un RP (Registro Presupuestal). | J18: Presupuesto definitivo cuyo bien o servicio aún no ha sido recibido/certificado (OPS).
A38: LECTURA EJECUTIVA
A39: ="El "&TEXT(J9,"0.0%")&" del presupuesto definitivo está comprometido (RP)."
A40: ="El "&TEXT(R9,"0.0%")&" del presupuesto definitivo ha sido efectivamente pagado."
A41: ="La brecha sin comprometer, respecto al total, es de $"&TEXT(F15,"#,##0")&"."
A44: SEGUIMIENTO POR COMPONENTE
A45: Componente | B45: Ppto. Definitivo | C45: Reservado CDP | D45: Comprometido RP | E45: Obligado OPS | F45: Pagado | G45: % Pag | H45: Sin Reservar | I45: Sin Comprometer | J45: Sin Obligar | K45: % Comp
A46: PRESTACION DEL SERVICIO | B46: =SUMIF(SEGUIMIENTO!$A$2:$A$5000,"PRESTACION DEL SERVICIO",SEGUIMIENTO!$H$2:$H$5000) | C46: =SUMIF(SEGUIMIENTO!$A$2:$A$5000,"PRESTACION DEL SERVICIO",SEGUIMIENTO!$I$2:$I$5000) | D46: =SUMIF(SEGUIMIENTO!$A$2:$A$5000,"PRESTACION DEL SERVICIO",SEGUIMIENTO!$J$2:$J$5000) | E46: =SUMIF(SEGUIMIENTO!$A$2:$A$5000,"PRESTACION DEL SERVICIO",SEGUIMIENTO!$K$2:$K$5000) | F46: =SUMIF(SEGUIMIENTO!$A$2:$A$5000,"PRESTACION DEL SERVICIO",SEGUIMIENTO!$L$2:$L$5000) | G46: =IFERROR(F46/B46,0) | H46: =B46-C46 | I46: =B46-D46 | J46: =B46-E46 | K46: =IFERROR(D46/B46,0)
A47: Nomina Docente, Directivo y Administrativo | B47: =SUMIFS(SEGUIMIENTO!$H$2:$H$5000,SEGUIMIENTO!$A$2:$A$5000,"PRESTACION DEL SERVICIO",SEGUIMIENTO!$U$2:$U$5000,"Nomina Docente, Directivo y Administrativo") | C47: =SUMIFS(SEGUIMIENTO!$I$2:$I$5000,SEGUIMIENTO!$A$2:$A$5000,"PRESTACION DEL SERVICIO",SEGUIMIENTO!$U$2:$U$5000,"Nomina Docente, Directivo y Administrativo") | D47: =SUMIFS(SEGUIMIENTO!$J$2:$J$5000,SEGUIMIENTO!$A$2:$A$5000,"PRESTACION DEL SERVICIO",SEGUIMIENTO!$U$2:$U$5000,"Nomina Docente, Directivo y Administrativo") | E47: =SUMIFS(SEGUIMIENTO!$K$2:$K$5000,SEGUIMIENTO!$A$2:$A$5000,"PRESTACION DEL SERVICIO",SEGUIMIENTO!$U$2:$U$5000,"Nomina Docente, Directivo y Administrativo") | F47: =SUMIFS(SEGUIMIENTO!$L$2:$L$5000,SEGUIMIENTO!$A$2:$A$5000,"PRESTACION DEL SERVICIO",SEGUIMIENTO!$U$2:$U$5000,"Nomina Docente, Directivo y Administrativo") | G47: =IFERROR(F47/B47,0) | H47: =B47-C47 | I47: =B47-D47 | J47: =B47-E47 | K47: =IFERROR(D47/B47,0)
A48: Sueldos Directivos Docentes Sin Situación de Fondos | B48: =SEGUIMIENTO!H2 | C48: =SEGUIMIENTO!I2 | D48: =SEGUIMIENTO!J2 | E48: =SEGUIMIENTO!K2 | F48: =SEGUIMIENTO!L2 | G48: =IFERROR(F48/B48,0) | H48: =B48-C48 | I48: =B48-D48 | J48: =B48-E48 | K48: =IFERROR(D48/B48,0)
A49: Sueldo Directivos Docentes Con Situación de Fondos | B49: =SEGUIMIENTO!H3 | C49: =SEGUIMIENTO!I3 | D49: =SEGUIMIENTO!J3 | E49: =SEGUIMIENTO!K3 | F49: =SEGUIMIENTO!L3 | G49: =IFERROR(F49/B49,0) | H49: =B49-C49 | I49: =B49-D49 | J49: =B49-E49 | K49: =IFERROR(D49/B49,0)
A50: Sueldo Administrativo | B50: =SEGUIMIENTO!H4 | C50: =SEGUIMIENTO!I4 | D50: =SEGUIMIENTO!J4 | E50: =SEGUIMIENTO!K4 | F50: =SEGUIMIENTO!L4 | G50: =IFERROR(F50/B50,0) | H50: =B50-C50 | I50: =B50-D50 | J50: =B50-E50 | K50: =IFERROR(D50/B50,0)
A51: Sueldo Docentes Con Situación de Fondos | B51: =SEGUIMIENTO!H5 | C51: =SEGUIMIENTO!I5 | D51: =SEGUIMIENTO!J5 | E51: =SEGUIMIENTO!K5 | F51: =SEGUIMIENTO!L5 | G51: =IFERROR(F51/B51,0) | H51: =B51-C51 | I51: =B51-D51 | J51: =B51-E51 | K51: =IFERROR(D51/B51,0)
A52: Sueldo Docentes Sin Situación de Fondos | B52: =SEGUIMIENTO!H6 | C52: =SEGUIMIENTO!I6 | D52: =SEGUIMIENTO!J6 | E52: =SEGUIMIENTO!K6 | F52: =SEGUIMIENTO!L6 | G52: =IFERROR(F52/B52,0) | H52: =B52-C52 | I52: =B52-D52 | J52: =B52-E52 | K52: =IFERROR(D52/B52,0)
A53: Horas Extra y días festivos Sin Situación de Fondos Directivos Docentes | B53: =SEGUIMIENTO!H7 | C53: =SEGUIMIENTO!I7 | D53: =SEGUIMIENTO!J7 | E53: =SEGUIMIENTO!K7 | F53: =SEGUIMIENTO!L7 | G53: =IFERROR(F53/B53,0) | H53: =B53-C53 | I53: =B53-D53 | J53: =B53-E53 | K53: =IFERROR(D53/B53,0)
A54: Horas Extras y días festivos Con Situación de Fondos Directivos Docentes | B54: =SEGUIMIENTO!H8 | C54: =SEGUIMIENTO!I8 | D54: =SEGUIMIENTO!J8 | E54: =SEGUIMIENTO!K8 | F54: =SEGUIMIENTO!L8 | G54: =IFERROR(F54/B54,0) | H54: =B54-C54 | I54: =B54-D54 | J54: =B54-E54 | K54: =IFERROR(D54/B54,0)
A55: Horas Extras y días festivos Administrativos | B55: =SEGUIMIENTO!H9 | C55: =SEGUIMIENTO!I9 | D55: =SEGUIMIENTO!J9 | E55: =SEGUIMIENTO!K9 | F55: =SEGUIMIENTO!L9 | G55: =IFERROR(F55/B55,0) | H55: =B55-C55 | I55: =B55-D55 | J55: =B55-E55 | K55: =IFERROR(D55/B55,0)
A56: Horas Extras y días festivos Sin Situación de Fondos Docentes | B56: =SEGUIMIENTO!H10 | C56: =SEGUIMIENTO!I10 | D56: =SEGUIMIENTO!J10 | E56: =SEGUIMIENTO!K10 | F56: =SEGUIMIENTO!L10 | G56: =IFERROR(F56/B56,0) | H56: =B56-C56 | I56: =B56-D56 | J56: =B56-E56 | K56: =IFERROR(D56/B56,0)
A57: Horas Extras y días festivos Con Situación de Fondos Docentes | B57: =SEGUIMIENTO!H11 | C57: =SEGUIMIENTO!I11 | D57: =SEGUIMIENTO!J11 | E57: =SEGUIMIENTO!K11 | F57: =SEGUIMIENTO!L11 | G57: =IFERROR(F57/B57,0) | H57: =B57-C57 | I57: =B57-D57 | J57: =B57-E57 | K57: =IFERROR(D57/B57,0)
A58: Subsidio o prima de alimentación Administrativo | B58: =SEGUIMIENTO!H12 | C58: =SEGUIMIENTO!I12 | D58: =SEGUIMIENTO!J12 | E58: =SEGUIMIENTO!K12 | F58: =SEGUIMIENTO!L12 | G58: =IFERROR(F58/B58,0) | H58: =B58-C58 | I58: =B58-D58 | J58: =B58-E58 | K58: =IFERROR(D58/B58,0)
A59: Subsidio o prima de alimentación Docentes | B59: =SEGUIMIENTO!H13 | C59: =SEGUIMIENTO!I13 | D59: =SEGUIMIENTO!J13 | E59: =SEGUIMIENTO!K13 | F59: =SEGUIMIENTO!L13 | G59: =IFERROR(F59/B59,0) | H59: =B59-C59 | I59: =B59-D59 | J59: =B59-E59 | K59: =IFERROR(D59/B59,0)
... A117: RF SGP- Prestación del Servicio educación | B117: =SEGUIMIENTO!H71 | C117: =SEGUIMIENTO!I71 | D117: =SEGUIMIENTO!J71 | E117: =SEGUIMIENTO!K71 | F117: =SEGUIMIENTO!L71 | G117: =IFERROR(F117/B117,0) | H117: =B117-C117 | I117: =B117-D117 | J117: =B117-E117 | K117: =IFERROR(D117/B117,0)
A118: Otros Gastos Administrativos | B118: =SUMIFS(SEGUIMIENTO!$H$2:$H$5000,SEGUIMIENTO!$A$2:$A$5000,"PRESTACION DEL SERVICIO",SEGUIMIENTO!$U$2:$U$5000,"Otros Gastos Administrativos") | C118: =SUMIFS(SEGUIMIENTO!$I$2:$I$5000,SEGUIMIENTO!$A$2:$A$5000,"PRESTACION DEL SERVICIO",SEGUIMIENTO!$U$2:$U$5000,"Otros Gastos Administrativos") | D118: =SUMIFS(SEGUIMIENTO!$J$2:$J$5000,SEGUIMIENTO!$A$2:$A$5000,"PRESTACION DEL SERVICIO",SEGUIMIENTO!$U$2:$U$5000,"Otros Gastos Administrativos") | E118: =SUMIFS(SEGUIMIENTO!$K$2:$K$5000,SEGUIMIENTO!$A$2:$A$5000,"PRESTACION DEL SERVICIO",SEGUIMIENTO!$U$2:$U$5000,"Otros Gastos Administrativos") | F118: =SUMIFS(SEGUIMIENTO!$L$2:$L$5000,SEGUIMIENTO!$A$2:$A$5000,"PRESTACION DEL SERVICIO",SEGUIMIENTO!$U$2:$U$5000,"Otros Gastos Administrativos") | G118: =IFERROR(F118/B118,0) | H118: =B118-C118 | I118: =B118-D118 | J118: =B118-E118 | K118: =IFERROR(D118/B118,0)
A119: Fortalecimiento de estrategias para la permanencia escolar otros administrativos | B119: =SEGUIMIENTO!H73 | C119: =SEGUIMIENTO!I73 | D119: =SEGUIMIENTO!J73 | E119: =SEGUIMIENTO!K73 | F119: =SEGUIMIENTO!L73 | G119: =IFERROR(F119/B119,0) | H119: =B119-C119 | I119: =B119-D119 | J119: =B119-E119 | K119: =IFERROR(D119/B119,0)
A120: SVC Aseo | B120: =SUMIFS(SEGUIMIENTO!$H$2:$H$5000,SEGUIMIENTO!$A$2:$A$5000,"PRESTACION DEL SERVICIO",SEGUIMIENTO!$U$2:$U$5000,"SVC Aseo") | C120: =SUMIFS(SEGUIMIENTO!$I$2:$I$5000,SEGUIMIENTO!$A$2:$A$5000,"PRESTACION DEL SERVICIO",SEGUIMIENTO!$U$2:$U$5000,"SVC Aseo") | D120: =SUMIFS(SEGUIMIENTO!$J$2:$J$5000,SEGUIMIENTO!$A$2:$A$5000,"PRESTACION DEL SERVICIO",SEGUIMIENTO!$U$2:$U$5000,"SVC Aseo") | E120: =SUMIFS(SEGUIMIENTO!$K$2:$K$5000,SEGUIMIENTO!$A$2:$A$5000,"PRESTACION DEL SERVICIO",SEGUIMIENTO!$U$2:$U$5000,"SVC Aseo") | F120: =SUMIFS(SEGUIMIENTO!$L$2:$L$5000,SEGUIMIENTO!$A$2:$A$5000,"PRESTACION DEL SERVICIO",SEGUIMIENTO!$U$2:$U$5000,"SVC Aseo") | G120: =IFERROR(F120/B120,0) | H120: =B120-C120 | I120: =B120-D120 | J120: =B120-E120 | K120: =IFERROR(D120/B120,0)
A121: Fortalecimiento de estrategias para la permanencia escolar svc aseo | B121: =SEGUIMIENTO!H75 | C121: =SEGUIMIENTO!I75 | D121: =SEGUIMIENTO!J75 | E121: =SEGUIMIENTO!K75 | F121: =SEGUIMIENTO!L75 | G121: =IFERROR(F121/B121,0) | H121: =B121-C121 | I121: =B121-D121 | J121: =B121-E121 | K121: =IFERROR(D121/B121,0)
...

Sheet SEGUIMIENTO
A1: Componente | B1: Naturaleza | C1: Codigo rubro | D1: cons_ppt | E1: Proyecto / Rubro | F1: Fondo | G1: Fuente | H1: Definitivo | I1: Reservado CDP | J1: Comprometido RP | K1: Obligado OPS | L1: Pagado | M1: Sin reservar | N1: Sin comprometer | O1: Sin obligar | P1: % Comp | Q1: % Pag | R1: Contratos | S1: Responsable | T1: Observacion | U1: Subgrupo
A2: PRESTACION DEL SERVICIO | B2: Nomina y aportes | C2: 02.01.2.3.1.01.01.001.01.001 | D2: 4865 | E2: Sueldos Directivos Docentes Sin Situación de Fondos | F2: 1.2.4.1.01 | G2: SGP-EDUCACION-PRESTACION DE SERVICIOS | H2: 371740660 | I2: 276440189 | J2: 276440189 | K2: 276440189 | L2: 276440189 | M2: =H2-I2 | N2: =I2-J2 | O2: =J2-K2 | P2: =IFERROR(J2/H2,"") | Q2: =IFERROR(L2/H2,"") | R2: Sin contratos | U2: Nomina Docente, Directivo y Administrativo
A3: PRESTACION DEL SERVICIO | B3: Nomina y aportes | C3: 02.01.2.3.1.01.01.001.01.002 | D3: 4866 | E3: Sueldo Directivos Docentes Con Situación de Fondos | F3: 1.2.4.1.01 | G3: SGP-EDUCACION-PRESTACION DE SERVICIOS | H3: 4127246171 | I3: 2946272302 | J3: 2944410737 | K3: 2944410737 | L3: 2944410737 | M3: =H3-I3 | N3: =I3-J3 | O3: =J3-K3 | P3: =IFERROR(J3/H3,"") | Q3: =IFERROR(L3/H3,"") | R3: Sin contratos | U3: Nomina Docente, Directivo y Administrativo
A4: PRESTACION DEL SERVICIO | B4: Nomina y aportes | C4: 02.01.2.3.1.01.01.001.01.003 | D4: 4867 | E4: Sueldo Administrativo | F4: 1.2.4.1.01 | G4: SGP-EDUCACION-PRESTACION DE SERVICIOS | H4: 449933960 | I4: 273314317 | J4: 273314317 | K4: 273314317 | L4: 273314317 | M4: =H4-I4 | N4: =I4-J4 | O4: =J4-K4 | P4: =IFERROR(J4/H4,"") | Q4: =IFERROR(L4/H4,"") | R4: Sin contratos | U4: Nomina Docente, Directivo y Administrativo
A5: PRESTACION DEL SERVICIO | B5: Nomina y aportes | C5: 02.01.2.3.1.01.01.001.01.004 | D5: 4868 | E5: Sueldo Docentes Con Situación de Fondos | F5: 1.2.4.1.01 | G5: SGP-EDUCACION-PRESTACION DE SERVICIOS | H5: 50187458743 | I5: 35442189914 | J5: 35442189914 | K5: 35442189914 | L5: 35442189914 | M5: =H5-I5 | N5: =I5-J5 | O5: =J5-K5 | P5: =IFERROR(J5/H5,"") | Q5: =IFERROR(L5/H5,"") | R5: Sin contratos | U5: Nomina Docente, Directivo y Administrativo
A6: PRESTACION DEL SERVICIO | B6: Nomina y aportes | C6: 02.01.2.3.1.01.01.001.01.005 | D6: 4869 | E6: Sueldo Docentes Sin Situación de Fondos | F6: 1.2.4.1.01 | G6: SGP-EDUCACION-PRESTACION DE SERVICIOS | H6: 4214618702 | I6: 3203544986 | J6: 3203544986 | K6: 3203544986 | L6: 3203544986 | M6: =H6-I6 | N6: =I6-J6 | O6: =J6-K6 | P6: =IFERROR(J6/H6,"") | Q6: =IFERROR(L6/H6,"") | R6: Sin contratos | U6: Nomina Docente, Directivo y Administrativo
A7: PRESTACION DEL SERVICIO | B7: Nomina y aportes | C7: 02.01.2.3.1.01.01.001.02.001 | D7: 4871 | E7: Horas Extra y días festivos Sin Situación de Fondos Directivos Docentes | F7: 1.2.4.1.01 | G7: SGP-EDUCACION-PRESTACION DE SERVICIOS | H7: 3973131 | I7: 3973131 | J7: 1578062 | K7: 1578062 | L7: 1578062 | M7: =H7-I7 | N7: =I7-J7 | O7: =J7-K7 | P7: =IFERROR(J7/H7,"") | Q7: =IFERROR(L7/H7,"") | R7: Sin contratos | U7: Nomina Docente, Directivo y Administrativo
A8: PRESTACION DEL SERVICIO | B8: Nomina y aportes | C8: 02.01.2.3.1.01.01.001.02.002 | D8: 4872 | E8: Horas Extras y días festivos Con Situación de Fondos Directivos Docentes | F8: 1.2.4.1.01 | G8: SGP-EDUCACION-PRESTACION DE SERVICIOS | H8: 29467958 | I8: 29467958 | J8: 18147722 | K8: 18147722 | L8: 18147722 | M8: =H8-I8 | N8: =I8-J8 | O8: =J8-K8 | P8: =IFERROR(J8/H8,"") | Q8: =IFERROR(L8/H8,"") | R8: Sin contratos | U8: Nomina Docente, Directivo y Administrativo
A9: PRESTACION DEL SERVICIO | B9: Nomina y aportes | C9: 02.01.2.3.1.01.01.001.02.003 | D9: 4873 | E9: Horas Extras y días festivos Administrativos | F9: 1.2.4.1.01 | G9: SGP-EDUCACION-PRESTACION DE SERVICIOS | H9: 73685952 | I9: 73685952 | J9: 20712030 | K9: 20712030 | L9: 20712030 | M9: =H9-I9 | N9: =I9-J9 | O9: =J9-K9 | P9: =IFERROR(J9/H9,"") | Q9: =IFERROR(L9/H9,"") | R9: Sin contratos | U9: Nomina Docente, Directivo y Administrativo
A10: PRESTACION DEL SERVICIO | B10: Nomina y aportes | C10: 02.01.2.3.1.01.01.001.02.004 | D10: 4874 | E10: Horas Extras y días festivos Sin Situación de Fondos Docentes | F10: 1.2.4.1.01 | G10: SGP-EDUCACION-PRESTACION DE SERVICIOS | H10: 60342374 | I10: 60342374 | J10: 42069697 | K10: 42069697 | L10: 42069697 | M10: =H10-I10 | N10: =I10-J10 | O10: =J10-K10 | P10: =IFERROR(J10/H10,"") | Q10: =IFERROR(L10/H10,"") | R10: Sin contratos | U10: Nomina Docente, Directivo y Administrativo
A11: PRESTACION DEL SERVICIO | B11: Nomina y aportes | C11: 02.01.2.3.1.01.01.001.02.005 | D11: 4875 | E11: Horas Extras y días festivos Con Situación de Fondos Docentes | F11: 1.2.4.1.01 | G11: SGP-EDUCACION-PRESTACION DE SERVICIOS | H11: 693937310 | I11: 693937310 | J11: 486380834 | K11: 486380834 | L11: 486380834 | M11: =H11-I11 | N11: =I11-J11 | O11: =J11-K11 | P11: =IFERROR(J11/H11,"") | Q11: =IFERROR(L11/H11,"") | R11: Sin contratos | U11: Nomina Docente, Directivo y Administrativo
A12: PRESTACION DEL SERVICIO | B12: Nomina y aportes | C12: 02.01.2.3.1.01.01.001.04.001 | D12: 4877 | E12: Subsidio o prima de alimentación Administrativo | F12: 1.2.4.1.01 | G12: SGP-EDUCACION-PRESTACION DE SERVICIOS | H12: 10652394 | I12: 5141074 | J12: 5141074 | K12: 5141074 | L12: 5141074 | M12: =H12-I12 | N12: =I12-J12 | O12: =J12-K12 | P12: =IFERROR(J12/H12,"") | Q12: =IFERROR(L12/H12,"") | R12: Sin contratos | U12: Nomina Docente, Directivo y Administrativo
A13: PRESTACION DEL SERVICIO | B13: Nomina y aportes | C13: 02.01.2.3.1.01.01.001.04.002 | D13: 4878 | E13: Subsidio o prima de alimentación Docentes | F13: 1.2.4.1.01 | G13: SGP-EDUCACION-PRESTACION DE SERVICIOS | H13: 29669138 | I13: 10020479 | J13: 10020479 | K13: 10020479 | L13: 10020479 | M13: =H13-I13 | N13: =I13-J13 | O13: =J13-K13 | P13: =IFERROR(J13/H13,"") | Q13: =IFERROR(L13/H13,"") | R13: Sin contratos | U13: Nomina Docente, Directivo y Administrativo
... A71: PRESTACION DEL SERVICIO | B71: Inversion / proyectos | C71: 02.01.2.3.2.02.02.009.110 | D71: 5827 | E71: RF SGP- Prestación del Servicio educación | F71: 1.3.2.2.01 | G71: R.F. SGP - EDUCACION-PRESTACION DE SERVICIO EDUCATIVO | H71: 0 | I71: 0 | J71: 0 | K71: 0 | L71: 0 | M71: =H71-I71 | N71: =I71-J71 | O71: =J71-K71 | P71: =IFERROR(J71/H71,"") | Q71: =IFERROR(L71/H71,"") | R71: Sin contratos | U71: Nomina Docente, Directivo y Administrativo
A72: SUBTOTAL Nomina Docente, Directivo y Administrativo | H72: =SUM(H2:H71) | I72: =SUM(I2:I71) | J72: =SUM(J2:J71) | K72: =SUM(K2:K71) | L72: =SUM(L2:L71) | M72: =H72-I72 | N72: =I72-J72 | O72: =J72-K72 | P72: =IFERROR(J72/H72,0) | Q72: =IFERROR(L72/H72,0)
A73: PRESTACION DEL SERVICIO | B73: Inversion / proyectos | C73: 02.01.2.3.2.02.02.009.028 | D73: 4965 | E73: Fortalecimiento de estrategias para la permanencia escolar otros administrativos | F73: 1.2.4.1.01 | G73: SGP-EDUCACION-PRESTACION DE SERVICIOS | H73: 785200240 | I73: 610842311 | J73: 480257600 | K73: 315000000 | L73: 315000000 | M73: =H73-I73 | N73: =I73-J73 | O73: =J73-K73 | P73: =IFERROR(J73/H73,"") | Q73: =IFERROR(L73/H73,"") | R73: Sin contratos | U73: Otros Gastos Administrativos
A74: SUBTOTAL Otros Gastos Administrativos | H74: =SUM(H73:H73) | I74: =SUM(I73:I73) | J74: =SUM(J73:J73) | K74: =SUM(K73:K73) | L74: =SUM(L73:L73) | M74: =H74-I74 | N74: =I74-J74 | O74: =J74-K74 | P74: =IFERROR(J74/H74,0) | Q74: =IFERROR(L74/H74,0)
A75: PRESTACION DEL SERVICIO | B75: Inversion / proyectos | C75: 02.01.2.3.2.02.02.009.026 | D75: 4963 | E75: Fortalecimiento de estrategias para la permanencia escolar svc aseo | F75: 1.2.4.1.01 | G75: SGP-EDUCACION-PRESTACION DE SERVICIOS | H75: 759871200 | I75: 759871200 | J75: 759871200 | K75: 0 | L75: 0 | M75: =H75-I75 | N75: =I75-J75 | O75: =J75-K75 | P75: =IFERROR(J75/H75,"") | Q75: =IFERROR(L75/H75,"") | R75: 1 contrato | $759,871,200 comprometido | U75: SVC Aseo
A76: SUBTOTAL SVC Aseo | H76: =SUM(H75:H75) | I76: =SUM(I75:I75) | J76: =SUM(J75:J75) | K76: =SUM(K75:K75) | L76: =SUM(L75:L75) | M76: =H76-I76 | N76: =I76-J76 | O76: =J76-K76 | P76: =IFERROR(J76/H76,0) | Q76: =IFERROR(L76/H76,0)
A77: PRESTACION DEL SERVICIO | B77: Inversion / proyectos | C77: 02.01.2.3.2.02.02.009.027 | D77: 4964 | E77: Fortalecimiento de estrategias para la permanencia escolar svc vigilancia | F77: 1.2.4.1.01 | G77: SGP-EDUCACION-PRESTACION DE SERVICIOS | H77: 759871200 | I77: 759871200 | J77: 759871200 | K77: 214080729 | L77: 214080729 | M77: =H77-I77 | N77: =I77-J77 | O77: =J77-K77 | P77: =IFERROR(J77/H77,"") | Q77: =IFERROR(L77/H77,"") | R77: Sin contratos | U77: SVC Vigilancia
A78: SUBTOTAL SVC Vigilancia | H78: =SUM(H77:H77) | I78: =SUM(I77:I77) | J78: =SUM(J77:J77) | K78: =SUM(K77:K77) | L78: =SUM(L77:L77) | M78: =H78-I78 | N78: =I78-J78 | O78: =J78-K78 | P78: =IFERROR(J78/H78,0) | Q78: =IFERROR(L78/H78,0)
A79: PRESTACION DEL SERVICIO | B79: Inversion / proyectos | C79: 02.01.2.3.2.02.02.009.029 | D79: 4966 | E79: Conectividad | F79: 1.2.4.1.01 | G79: SGP-EDUCACION-PRESTACION DE SERVICIOS | H79: 417066544 | I79: 0 | J79: 0 | K79: 0 | L79: 0 | M79: =H79-I79 | N79: =I79-J79 | O79: =J79-K79 | P79: =IFERROR(J79/H79,"") | Q79: =IFERROR(L79/H79,"") | R79: Sin contratos | U79: Conectividad
A80: SUBTOTAL Conectividad | H80: =SUM(H79:H79) | I80: =SUM(I79:I79) | J80: =SUM(J79:J79) | K80: =SUM(K79:K79) | L80: =SUM(L79:L79) | M80: =H80-I80 | N80: =I80-J80 | O80: =J80-K80 | P80: =IFERROR(J80/H80,0) | Q80: =IFERROR(L80/H80,0)
A81: PRESTACION DEL SERVICIO | B81: Inversion / proyectos | C81: 02.01.2.3.2.02.02.009.030 | D81: 4967 | E81: Atención a población con necesidades especiales o discapacidades | F81: 1.2.4.1.01 | G81: SGP-EDUCACION-PRESTACION DE SERVICIOS | H81: 379869229 | I81: 379869229 | J81: 379869229 | K81: 379869229 | L81: 379869229 | M81: =H81-I81 | N81: =I81-J81 | O81: =J81-K81 | P81: =IFERROR(J81/H81,"") | Q81: =IFERROR(L81/H81,"") | R81: 1 contrato | $379,869,229 comprometido | U81: Necesidades Educativas Especiales
A82: SUBTOTAL Necesidades Educativas Especiales | H82: =SUM(H81:H81) | I82: =SUM(I81:I81) | J82: =SUM(J81:J81) | K82: =SUM(K81:K81) | L82: =SUM(L81:L81) | M82: =H82-I82 | N82: =I82-J82 | O82: =J82-K82 | P82: =IFERROR(J82/H82,0) | Q82: =IFERROR(L82/H82,0)
A83: SUBTOTAL PRESTACION DEL SERVICIO | H83: =SUM(H72,H74,H76,H78,H80,H82) | I83: =SUM(I72,I74,I76,I78,I80,I82) | J83: =SUM(J72,J74,J76,J78,J80,J82) | K83: =SUM(K72,K74,K76,K78,K80,K82) | L83: =SUM(L72,L74,L76,L78,L80,L82) | M83: =H83-I83 | N83: =I83-J83 | O83: =J83-K83 | P83: =IFERROR(J83/H83,0) | Q83: =IFERROR(L83/H83,0)
A84: RECURSOS PROPIOS O LIBRE INVERSION | B84: Inversion / proyectos | C84: 02.01.2.3.2.02.02.005.009 | D84: 5869 | E84: 020103 Ciudadela Educativa Etapa 1 | F84: 1.3.1.1.05.04 | G84: RECURSOS DE CREDITO INTERNO | H84: 42000000000 | I84: 34257295709 | J84: 34257295709 | K84: 15399242347 | L84: 15399242347 | M84: =H84-I84 | N84: =I84-J84 | O84: =J84-K84 | P84: =IFERROR(J84/H84,"") | Q84: =IFERROR(L84/H84,"") | R84: Sin contratos | U84: RECURSOS PROPIOS O LIBRE INVERSION
A85: RECURSOS PROPIOS O LIBRE INVERSION | B85: Inversion / proyectos | C85: 02.01.2.3.2.02.02.009.031 | D85: 4976 | E85: 020102 Formulación e implementación del plan Decenal de Educación | F85: 1.2.1.0.00 | G85: INGRESOS CORRIENTES DE LIBRE DESTINACION | H85: 0 | I85: 0 | J85: 0 | K85: 0 | L85: 0 | M85: =H85-I85 | N85: =I85-J85 | O85: =J85-K85 | P85: =IFERROR(J85/H85,"") | Q85: =IFERROR(L85/H85,"") | R85: Sin contratos | U85: RECURSOS PROPIOS O LIBRE INVERSION
A86: RECURSOS PROPIOS O LIBRE INVERSION | B86: Inversion / proyectos | C86: 02.01.2.3.2.02.02.009.038 | D86: 4981 | E86: 020105 Desarrollo del programa de bienestar para docentes y directivos docentes | F86: 1.2.1.0.00 | G86: INGRESOS CORRIENTES DE LIBRE DESTINACION | H86: 261614015 | I86: 261614015 | J86: 18195388 | K86: 18195388 | L86: 18195388 | M86: =H86-I86 | N86: =I86-J86 | O86: =J86-K86 | P86: =IFERROR(J86/H86,"") | Q86: =IFERROR(L86/H86,"") | R86: Sin contratos | U86: RECURSOS PROPIOS O LIBRE INVERSION
A87: RECURSOS PROPIOS O LIBRE INVERSION | B87: Inversion / proyectos | C87: 02.01.2.3.2.02.02.009.039 | D87: 4985 | E87: 020106 Mejoramiento de la cobertura Educativa PAE | F87: 1.2.1.0.00 | G87: INGRESOS CORRIENTES DE LIBRE DESTINACION | H87: 27344058931 | I87: 27344058931 | J87: 27217166386 | K87: 7985014808 | L87: 7548707923 | M87: =H87-I87 | N87: =I87-J87 | O87: =J87-K87 | P87: =IFERROR(J87/H87,"") | Q87: =IFERROR(L87/H87,"") | R87: 6 contratos | $27,217,166,386 comprometido | U87: RECURSOS PROPIOS O LIBRE INVERSION
A88: RECURSOS PROPIOS O LIBRE INVERSION | B88: Inversion / proyectos | C88: 02.01.2.3.2.02.02.009.040 | D88: 4986 | E88: 020106 Mejoramiento de la cobertura Educativa Paquetes PAE | F88: 1.2.1.0.00 | G88: INGRESOS CORRIENTES DE LIBRE DESTINACION | H88: 7721361064 | I88: 7338263218 | J88: 7320703987 | K88: 3411171557 | L88: 1133544243 | M88: =H88-I88 | N88: =I88-J88 | O88: =J88-K88 | P88: =IFERROR(J88/H88,"") | Q88: =IFERROR(L88/H88,"") | R88: 1 contrato | $3,794,269,403 comprometido | U88: RECURSOS PROPIOS O LIBRE INVERSION
A89: RECURSOS PROPIOS O LIBRE INVERSION | B89: Inversion / proyectos | C89: 02.01.2.3.2.02.02.009.042 | D89: 4972 | E89: 020101 VF Fortalecimiento de la pertinencia y la calidad educativa | F89: 1.2.1.0.00 | G89: INGRESOS CORRIENTES DE LIBRE DESTINACION | H89: 3.0865868e+09 | I89: 2902424207 | J89: 2902424207 | K89: 2902424207 | L89: 2902424207 | M89: =H89-I89 | N89: =I89-J89 | O89: =J89-K89 | P89: =IFERROR(J89/H89,"") | Q89: =IFERROR(L89/H89,"") | R89: 2 contratos | $2,902,424,207 comprometido | U89: RECURSOS PROPIOS O LIBRE INVERSION
A90: RECURSOS PROPIOS O LIBRE INVERSION | B90: Inversion / proyectos | C90: 02.01.2.3.2.02.02.009.043 | D90: 4973 | E90: 020101 Fortalecimiento de la pertinencia y la calidad educativa | F90: 1.2.1.0.00 | G90: INGRESOS CORRIENTES DE LIBRE DESTINACION | H90: 109270604 | I90: 45506000 | J90: 20306000 | K90: 11213763 | L90: 11213763 | M90: =H90-I90 | N90: =I90-J90 | O90: =J90-K90 | P90: =IFERROR(J90/H90,"") | Q90: =IFERROR(L90/H90,"") | R90: 1 contrato | $20,306,000 comprometido | U90: RECURSOS PROPIOS O LIBRE INVERSION
A91: RECURSOS PROPIOS O LIBRE INVERSION | B91: Inversion / proyectos | C91: 02.01.2.3.2.02.02.009.044 | D91: 4995 | E91: 020107 Fortalecimiento del programa de Bilinguismo | F91: 1.2.1.0.00 | G91: INGRESOS CORRIENTES DE LIBRE DESTINACION | H91: 2125253816 | I91: 1530633596 | J91: 1530633596 | K91: 0 | L91: 0 | M91: =H91-I91 | N91: =I91-J91 | O91: =J91-K91 | P91: =IFERROR(J91/H91,"") | Q91: =IFERROR(L91/H91,"") | R91: 1 contrato | $941,332,078 comprometido | U91: RECURSOS PROPIOS O LIBRE INVERSION
A92: RECURSOS PROPIOS O LIBRE INVERSION | B92: Inversion / proyectos | C92: 02.01.2.3.2.02.02.009.045 | D92: 4979 | E92: 020104 Fortalecimiento de la Educación técnica, tecnológica y superior | F92: 1.2.1.0.00 | G92: INGRESOS CORRIENTES DE LIBRE DESTINACION | H92: 750999040 | I92: 750999040 | J92: 463568362 | K92: 463568362 | L92: 201282900 | M92: =H92-I92 | N92: =I92-J92 | O92: =J92-K92 | P92: =IFERROR(J92/H92,"") | Q92: =IFERROR(L92/H92,"") | R92: Sin contratos | U92: RECURSOS PROPIOS O LIBRE INVERSION
A93: RECURSOS PROPIOS O LIBRE INVERSION | B93: Inversion / proyectos | C93: 02.01.2.3.2.02.02.009.046 | D93: 4996 | E93: 020108 Fortalecimiento del Bienestar Institucional | F93: 1.2.1.0.00 | G93: INGRESOS CORRIENTES DE LIBRE DESTINACION | H93: 8346289732 | I93: 7941535948 | J93: 7663802309 | K93: 798613653 | L93: 386530709 | M93: =H93-I93 | N93: =I93-J93 | O93: =J93-K93 | P93: =IFERROR(J93/H93,"") | Q93: =IFERROR(L93/H93,"") | R93: 3 contratos | $4,222,234,277 comprometido | U93: RECURSOS PROPIOS O LIBRE INVERSION
A94: RECURSOS PROPIOS O LIBRE INVERSION | B94: Inversion / proyectos | C94: 02.01.2.3.2.02.02.009.047 | D94: 4974 | E94: 020101 Fortalecimiento de la pertinencia y la calidad educativa | F94: 1.2.1.0.00 | G94: INGRESOS CORRIENTES DE LIBRE DESTINACION | H94: 1250429381 | I94: 1250429381 | J94: 0 | K94: 0 | L94: 0 | M94: =H94-I94 | N94: =I94-J94 | O94: =J94-K94 | P94: =IFERROR(J94/H94,"") | Q94: =IFERROR(L94/H94,"") | R94: Sin contratos | U94: RECURSOS PROPIOS O LIBRE INVERSION
A95: RECURSOS PROPIOS O LIBRE INVERSION | B95: Inversion / proyectos | C95: 02.01.2.3.2.02.02.009.048 | D95: 4987 | E95: 020106 Mejoramiento de la cobertura Educativa Equipo | F95: 1.2.1.0.00 | G95: INGRESOS CORRIENTES DE LIBRE DESTINACION | H95: 0 | I95: 0 | J95: 0 | K95: 0 | L95: 0 | M95: =H95-I95 | N95: =I95-J95 | O95: =J95-K95 | P95: =IFERROR(J95/H95,"") | Q95: =IFERROR(L95/H95,"") | R95: Sin contratos | U95: RECURSOS PROPIOS O LIBRE INVERSION
... A98: RECURSOS PROPIOS O LIBRE INVERSION | B98: Inversion / proyectos | C98: 02.01.2.3.2.02.02.009.085 | D98: 4978 | E98: 020103 Fortalecimiento de Infraestructura y Ambientes de Aprendizaje para el bienestar | F98: 1.2.1.0.00 | G98: INGRESOS CORRIENTES DE LIBRE DESTINACION | H98: 0 | I98: 0 | J98: 0 | K98: 0 | L98: 0 | M98: =H98-I98 | N98: =I98-J98 | O98: =J98-K98 | P98: =IFERROR(J98/H98,"") | Q98: =IFERROR(L98/H98,"") | R98: Sin contratos | U98: RECURSOS PROPIOS O LIBRE INVERSION
A99: SUBTOTAL RECURSOS PROPIOS O LIBRE INVERSION | H99: =SUM(H84:H98) | I99: =SUM(I84:I98) | J99: =SUM(J84:J98) | K99: =SUM(K84:K98) | L99: =SUM(L84:L98) | M99: =H99-I99 | N99: =I99-J99 | O99: =J99-K99 | P99: =IFERROR(J99/H99,0) | Q99: =IFERROR(L99/H99,0)
...

Sheet CONTRATOS
A1: Nro contrato | B1: Contratista | C1: Objeto | D1: cons_ppt | E1: Proyecto / Rubro | F1: Componente | G1: Fuente | H1: Valor contrato | I1: Comprometido | J1: Obligado | K1: Pagado | L1: Saldo x pagar | M1: % Ejec | N1: CDP | O1: RP | P1: Vig Futura | Q1: Estado | R1: Match | S1: Suscripcion | T1: Supervisor | U1: Observacion
A2: 10.14.00.00-22.15-006-2026 | B2: EQS DOTACIONES | D2: 4959 | E2: Dotación Ley 70/88 Docentes | F2: PRESTACION DEL SERVICIO | G2: SGP-EDUCACION-PRESTACION DE SERVICIOS | H2: 18018000 | I2: 18018000 | J2: 0 | K2: 0 | L2: 18018000 | M2: 0 | N2: 377 | R2: OK - match unico por # de CDP
A3: 10.14.00.00-23.01-009-2026 | B3: UNIÓN TEMPORAL OPERACIÓN EDUCATIVA RIONEGRO (I.E) | D3: 4963 | E3: Fortalecimiento de estrategias para la permanencia escolar svc aseo | F3: PRESTACION DEL SERVICIO | G3: SGP-EDUCACION-PRESTACION DE SERVICIOS | H3: 6616274792 | I3: 759871200 | J3: 0 | K3: 0 | L3: 6616274792 | M3: 0 | N3: 474 | R3: OK - match por CDP + codigo (CDP compartido)
A4: 10.14.00.00-21.12-007-2026 | B4: WPR GESTION EN SALUD S.A.S | D4: 4967 | E4: Atención a población con necesidades especiales o discapacidades | F4: PRESTACION DEL SERVICIO | G4: SGP-EDUCACION-PRESTACION DE SERVICIOS | H4: 4280761543 | I4: 379869229 | J4: 0 | K4: 379869229 | L4: 3900892314 | M4: 0.088738703 | N4: 196 | R4: OK - match por CDP + codigo (CDP compartido)
A5: 10.13.00-22.01-006-2025 | B5: EQUIDE SER | D5: 4972 | E5: 020101 VF Fortalecimiento de la pertinencia y la calidad educativa | F5: RECURSOS PROPIOS O LIBRE INVERSION | G5: INGRESOS CORRIENTES DE LIBRE DESTINACION | H5: 0 | I5: 1329649621 | J5: 0 | K5: 1329649621 | L5: -1329649621 | M5: — | N5: 28 | R5: OK - match unico por # de CDP
A6: 1120-07-021-2024 Esal 018 2024 | B6: EQUIDE I.E 2024-2025 | D6: 4972 | E6: 020101 VF Fortalecimiento de la pertinencia y la calidad educativa | F6: RECURSOS PROPIOS O LIBRE INVERSION | G6: INGRESOS CORRIENTES DE LIBRE DESTINACION | H6: 0 | I6: 1572774586 | J6: 0 | K6: 1572774586 | L6: -1572774586 | M6: — | N6: 29 | R6: OK - match unico por # de CDP
A7: 10.14.00.00-21.12-017-2026 | B7: GMA DIGITAL S.A.S. | D7: 4973 | E7: 020101 Fortalecimiento de la pertinencia y la calidad educativa | F7: RECURSOS PROPIOS O LIBRE INVERSION | G7: INGRESOS CORRIENTES DE LIBRE DESTINACION | H7: 20306000 | I7: 20306000 | J7: 0 | K7: 13032211 | L7: 7273789 | M7: 0.64179115 | N7: 30 | R7: OK - match unico por # de CDP
A8: 10.14.00.00-21.16-003-2026 | B8: UNIÓN TEMPORAL UDEA E INSTITUTO PARA EL DESARROLLO DE ANTIOQUIA -IDEA | D8: 4980 | E8: 020104 Fortalecimiento de la Educación técnica, tecnológica y superior | F8: RECURSOS PROPIOS O LIBRE INVERSION | G8: INGRESOS CORRIENTES DE LIBRE DESTINACION | H8: 849004703 | I8: 849004703 | J8: 0 | K8: 621845949 | L8: 227158754 | M8: 0.73244111 | N8: 269 | R8: OK - match unico por # de CDP
A9: 10.13.00-21.16-041-2025 | B9: NUTRICERES NUEVO 2025-2026 | D9: 4985 | E9: 020106 Mejoramiento de la cobertura Educativa PAE | F9: RECURSOS PROPIOS O LIBRE INVERSION | G9: INGRESOS CORRIENTES DE LIBRE DESTINACION | H9: 0 | I9: 26890794978 | J9: 0 | K9: 7798093002 | L9: -7798093002 | M9: — | N9: 136 | R9: OK - match por CDP + codigo (CDP compartido)
A10: 10.14.00.00-21.12-008-2026 | B10: Juan Camilo Restrepo Rodriguez | D10: 4985 | E10: 020106 Mejoramiento de la cobertura Educativa PAE | F10: RECURSOS PROPIOS O LIBRE INVERSION | G10: INGRESOS CORRIENTES DE LIBRE DESTINACION | H10: 72879048 | I10: 72879048 | J10: 0 | K10: 48365186 | L10: 24513862 | M10: 0.66363636 | N10: 26 | R10: OK - match unico por # de CDP
A11: 10.14.00.00-21.12-009-2026 | B11: Ana Cecilia Franco Marin | D11: 4985 | E11: 020106 Mejoramiento de la cobertura Educativa PAE | F11: RECURSOS PROPIOS O LIBRE INVERSION | G11: INGRESOS CORRIENTES DE LIBRE DESTINACION | H11: 63373090 | I11: 63373090 | J11: 0 | K11: 42056687 | L11: 21316403 | M11: 0.66363636 | N11: 23 | R11: OK - match unico por # de CDP
A12: 10.14.00.00-21.12-014-2026 | B12: Maria Fernanda Montoya Guarin | D12: 4985 | E12: 020106 Mejoramiento de la cobertura Educativa PAE | F12: RECURSOS PROPIOS O LIBRE INVERSION | G12: INGRESOS CORRIENTES DE LIBRE DESTINACION | H12: 63373090 | I12: 63373090 | J12: 0 | K12: 42056687 | L12: 21316403 | M12: 0.66363636 | N12: 22 | R12: OK - match unico por # de CDP
A13: 10.14.00.00-21.12-015-2026 | B13: Andrés Felipe Pardo Martínez | D13: 4985 | E13: 020106 Mejoramiento de la cobertura Educativa PAE | F13: RECURSOS PROPIOS O LIBRE INVERSION | G13: INGRESOS CORRIENTES DE LIBRE DESTINACION | H13: 63373090 | I13: 63373090 | J13: 0 | K13: 42056687 | L13: 21316403 | M13: 0.66363636 | N13: 27 | R13: OK - match unico por # de CDP
A14: 10.14.00.00-21.12-016-2026 | B14: Maria Catherine Soto Garcia | D14: 4985 | E14: 020106 Mejoramiento de la cobertura Educativa PAE | F14: RECURSOS PROPIOS O LIBRE INVERSION | G14: INGRESOS CORRIENTES DE LIBRE DESTINACION | H14: 63373090 | I14: 63373090 | J14: 0 | K14: 42056687 | L14: 21316403 | M14: 0.66363636 | N14: 24 | R14: OK - match unico por # de CDP
A15: 10.13.00-21.16-015-2025 | B15: NUTRICERES (Paquetes) | D15: 4986 | E15: 020106 Mejoramiento de la cobertura Educativa Paquetes PAE | F15: RECURSOS PROPIOS O LIBRE INVERSION | G15: INGRESOS CORRIENTES DE LIBRE DESTINACION | H15: 0 | I15: 3794269403 | J15: 0 | K15: 3411171557 | L15: -3411171557 | M15: — | N15: 135 | R15: OK - match unico por # de CDP
A16: 10.14.00.00-23.01-022-2026 ESAL 026 2026 | B16: COLOMBO AMERICANO MEDELLIN | D16: 4995 | E16: 020107 Fortalecimiento del programa de Bilinguismo | F16: RECURSOS PROPIOS O LIBRE INVERSION | G16: INGRESOS CORRIENTES DE LIBRE DESTINACION | H16: 941332078 | I16: 941332078 | J16: 0 | K16: 0 | L16: 941332078 | M16: 0 | N16: 375 | R16: OK - match unico por # de CDP
A17: 10.13.00-21.12-067-2025 | B17: COMFAMA | D17: 4996 | E17: 020108 Fortalecimiento del Bienestar Institucional | F17: RECURSOS PROPIOS O LIBRE INVERSION | G17: INGRESOS CORRIENTES DE LIBRE DESTINACION | H17: 0 | I17: 578755999 | J17: 0 | K17: 198002215 | L17: -198002215 | M17: — | N17: 171 | R17: OK - match unico por # de CDP
A18: 10.14.00.00-23.01-020-2026 | B18: EQUIDE SER (Administrativos) | D18: 4996 | E18: 020108 Fortalecimiento del Bienestar Institucional | F18: RECURSOS PROPIOS O LIBRE INVERSION | G18: INGRESOS CORRIENTES DE LIBRE DESTINACION | H18: 3381349180 | I18: 3381349180 | J18: 0 | K18: 0 | L18: 3381349180 | M18: 0 | N18: 897 | R18: OK - match unico por # de CDP
A19: 1120-07-021-2024 Esal 018 2024 | B19: EQUIDE I.E 2024-2025 | D19: 4996 | E19: 020108 Fortalecimiento del Bienestar Institucional | F19: RECURSOS PROPIOS O LIBRE INVERSION | G19: INGRESOS CORRIENTES DE LIBRE DESTINACION | H19: 0 | I19: 262129098 | J19: 0 | K19: 262129098 | L19: -262129098 | M19: — | N19: 566 | R19: OK - match unico por # de CDP
A20: 10.13.00-21.16-041-2025 | B20: NUTRICERES NUEVO 2025-2026 | D20: 4983 | E20: 020106 Mejoramiento de la cobertura Educativa PAE | F20: SGP - PGN - PAE | G20: SGP-ASIGNACION ESPECIAL-PROGRAMAS DE ALIMENTACION ESCOLAR | H20: 0 | I20: 173769267 | J20: 0 | K20: 0 | L20: 0 | M20: — | N20: 845 | R20: OK - match unico por # de CDP
A21: 10.13.00-21.16-041-2025 | B21: NUTRICERES NUEVO 2025-2026 | D21: 6806 | E21: 020106 Mejoramiento de la cobertura Educativa PAE | F21: SGP - PGN - PAE | G21: R.B. APORTES NACION - ALIMENTACION ESCOLAR | H21: 0 | I21: 2.5451226e+08 | J21: 0 | K21: 2.5451226e+08 | L21: -2.5451226e+08 | M21: — | N21: 483 | R21: OK - match unico por # de CDP
A22: 10.14.00.00-23.01-013-2026 | B22: CORPOASES - SALA CUNAS | D22: 6848 | E22: 010101 Acompañamiento en la atención a la primera infancia | F22: PRIMERA INFANCIA | G22: INGRESOS CORRIENTES DE LIBRE DESTINACION | H22: 1555487503 | I22: 1555487503 | J22: 0 | K22: 43727430 | L22: 1511760073 | M22: 0.028111721 | N22: 509 | R22: OK - match unico por # de CDP
A23: 1120-07-021-2024 Esal 018 2024 | B23: EQUIDE I.E 2024-2025 | D23: 3767 | F23: (otra Secretaria) | H23: 0 | I23: 710160000 | J23: 0 | K23: 7.1016e+08 | L23: -7.1016e+08 | M23: — | N23: 93 | R23: OK - match unico por # de CDP
A24: 10.13.00-21.12-067-2025 | B24: COMFAMA | D24: 3806 | F24: (otra Secretaria) | H24: 1268286939 | I24: 689530940 | J24: 0 | K24: 689530940 | L24: 578755999 | M24: 0.54367109 | N24: 1106 | R24: OK - match unico por # de CDP
A25: 10.14.00.00-21.16-069-2025 | B25: ESO RIONEGRO S.A.S | D25: 3806 | F25: (otra Secretaria) | H25: 356690601 | I25: 356690601 | J25: 0 | K25: 130015816 | L25: 226674785 | M25: 0.36450586 | N25: 421 | R25: OK - match unico por # de CDP
A26: 10.13.00-21.16-015-2025 | B26: NUTRICERES (Paquetes) | D26: 5317 | F26: (otra Secretaria) | H26: 11382808209 | I26: 7588538806 | J26: 0 | K26: 5029097642 | L26: 6353710567 | M26: 0.4418152 | N26: 218 | R26: OK - match unico por # de CDP
A27: 10.13.00-21.16-052-2025 | B27: CORPORACIÓN GILBERTO ECHEVERRI MEJÍA | D27: 6895 | F27: (otra Secretaria) | H27: 486556410 | I27: 220406565 | J27: 0 | K27: 166912664 | L27: 319643746 | M27: 0.34304895 | N27: 1107 | R27: OK - match unico por # de CDP
A28: 10.13.00-21.12-067-2025 | B28: COMFAMA | F28: (vigencia futura -- otro periodo) | H28: 0 | I28: 435682534 | J28: 0 | K28: 0 | L28: 0 | M28: — | N28: -20251106 | P28: 2025 | R28: Vigencia futura de otro periodo (normal)
A29: 10.13.00-21.16-015-2025 | B29: NUTRICERES (Paquetes) | F29: (vigencia futura -- otro periodo) | H29: 0 | I29: 2559441164 | J29: 0 | K29: 2559441164 | L29: -2559441164 | M29: — | N29: -2025218 | P29: 2025 | R29: Vigencia futura de otro periodo (normal)
A30: 10.13.00-21.16-041-2025 | B30: NUTRICERES NUEVO 2025-2026 | F30: (vigencia futura -- otro periodo) | H30: 0 | I30: 7.3477494e+09 | J30: 0 | K30: 0 | L30: 0 | M30: — | N30: -2025991 | P30: 2025 | R30: Vigencia futura de otro periodo (normal)
A31: 10.13.00-21.16-052-2025 | B31: CORPORACIÓN GILBERTO ECHEVERRI MEJÍA | F31: (vigencia futura -- otro periodo) | H31: 0 | I31: 220406565 | J31: 0 | K31: 0 | L31: 0 | M31: — | N31: -20251107 | P31: 2025 | R31: Vigencia futura de otro periodo (normal)
A32: 10.13.00-22.01-006-2025 | B32: EQUIDE SER | F32: (vigencia futura -- otro periodo) | H32: 0 | I32: 755745927 | J32: 0 | K32: 755745927 | L32: -755745927 | M32: — | N32: -20256 | P32: 2025 | R32: Vigencia futura de otro periodo (normal)
A33: 10.13.00-22.01-014-2025 | B33: EQUIDE ESAL 015 2025 (PLAN DECENAL) | F33: (vigencia futura -- otro periodo) | H33: 0 | I33: 104407076 | J33: 0 | K33: 0 | L33: 0 | M33: — | N33: -2025423 | P33: 2025 | R33: Vigencia futura de otro periodo (normal)
A34: 10.14.00.00-21.16-069-2025 | B34: ESO RIONEGRO S.A.S | F34: (vigencia futura -- otro periodo) | H34: 0 | I34: 226674785 | J34: 0 | K34: 47530294 | L34: -47530294 | M34: — | N34: -2025421 | P34: 2025 | R34: Vigencia futura de otro periodo (normal)
A35: 1120-07-021-2024 Esal 018 2024 | B35: EQUIDE I.E 2024-2025 | F35: (vigencia futura -- otro periodo) | H35: 8424574030 | I35: 150000000 | J35: 0 | K35: 150000000 | L35: 8274574030 | M35: 0.017805055 | N35: -20241412 | P35: 2024 | R35: Vigencia futura de otro periodo (normal)
A36: 1120-07-021-2024 Esal 018 2024 | B36: EQUIDE I.E 2024-2025 | F36: (vigencia futura -- otro periodo) | H36: 0 | I36: 257500313 | J36: 0 | K36: 257500313 | L36: -257500313 | M36: — | N36: -202593 | P36: 2025 | R36: Vigencia futura de otro periodo (normal)
A37: 10.13.00-21.16-041-2025 | B37: NUTRICERES NUEVO 2025-2026 | F37: (SIN RESOLVER -- revisar) | H37: 42991910142 | I37: 410795944 | J37: 0 | K37: 410795944 | L37: 42581114198 | M37: 0.0095551917 | N37: 991 | R37: AMBIGUO -- CDP compartido por: 4871,4872
A38: 10.13.00-21.16-041-2025 | B38: NUTRICERES NUEVO 2025-2026 | F38: (SIN RESOLVER -- revisar) | H38: 0 | I38: 1049611.4 | J38: 0 | K38: 1049611.4 | L38: -1049611.4 | M38: — | N38: 1528 | R38: CDP no aparece en el Hacienda de este corte
A39: 10.13.00-22.01-006-2025 | B39: EQUIDE SER | F39: (SIN RESOLVER -- revisar) | H39: 3995143725 | I39: 2665494104 | J39: 0 | K39: 1909748177 | L39: 2085395548 | M39: 0.47801739 | N39: 6 | R39: AMBIGUO -- CDP compartido por: 5304,5307,6076
A40: 10.13.00-22.01-014-2025 | B40: EQUIDE ESAL 015 2025 (PLAN DECENAL) | F40: (SIN RESOLVER -- revisar) | H40: 407239644 | I40: 407239644 | J40: 0 | K40: 302832568 | L40: 104407076 | M40: 0.74362251 | N40: 423 | R40: AMBIGUO -- CDP compartido por: 4874,4875
...

Sheet NOTAS
A1: Tema | B1: Explicacion
A2: Corte | B2: 15/09/2026 — tomado del nombre del archivo de Hacienda.
A3: Alcance | B3: Vigencia 2026. Es de Educacion todo rubro cuyo cons_ppt esta en la lista maestra RUBROS_EDUCACION (127 cons_ppt confirmados uno por uno sobre el corte 15_09_2026), menos EXCLUSIONES. Se excluye 'Cierre de reservas'. El codigo (02.01/01.01) NO se usa para clasificar: hay rubros hermanos bajo el mismo codigo padre que son de otra Secretaria. El color de cada fila lo pone el sistema solo (MAPA_COLORES); el usuario no tiene que colorear el archivo de Hacienda.
A4: Definitivo | B4: Apropiacion inicial +/- adiciones, reducciones y traslados.
A5: Reservado (CDP) | B5: Certificado de Disponibilidad Presupuestal.
A6: Comprometido (RP) | B6: Registro Presupuestal — respalda contrato u obligacion.
A7: Obligado (OPS) | B7: Orden de Pago — obligacion reconocida y exigible.
A8: Pagado | B8: Giro efectivo. En esta entidad suele coincidir con el obligado del corte.
A9: Sin reservar / comprometer / obligar | B9: Brecha entre una etapa y la siguiente.
A10: Componente | B10: Clasificacion por fuente. Ver hoja EJECUTIVO.
A11: Contratos | B11: Se cargan en seguimiento_manual_educacion.xlsx (hoja CONTRATOS). Cada corrida de GENERAR_INFORME.bat los vuelve a leer: lo que este alli aparece aqui, no hay que copiar nada.
A12: Conciliacion — definitiva | B12: Informe: 219,806,760,754. Seguimiento manual 15/08/2026: 219,422,883,163. Diferencia: 383,877,591.
... A16: Generado | B16: 2026-09-18
